
В результате выполнения получим вывод на консоль:

1. Got the Test Exception
   Inside finally block